<?xml version="1.0" encoding="UTF-8"?>
<!-- Generated by org.testng.reporters.JUnitReportReporter -->
<testsuite skipped="0" hostname="DESKTOP-HR6DLCF" name="test_cases.Login_Test" tests="31" failures="2" timestamp="07 Aug 2017 05:10:55 GMT" time="26.341" errors="0">
  <testcase name="Test_Login_Admin" time="1.585" classname="test_cases.Login_Test"/>
  <testcase name="Test_Login" time="2.012" classname="test_cases.Login_Test"/>
  <testcase name="Test_Login_Admin" time="0.063" classname="test_cases.Login_Test"/>
  <testcase name="Test_Login" time="0.146" classname="test_cases.Login_Test"/>
  <testcase name="Test_Login" time="2.008" classname="test_cases.Login_Test"/>
  <testcase name="Test_Login" time="0.120" classname="test_cases.Login_Test"/>
  <testcase name="Test_Login_Admin" time="2.011" classname="test_cases.Login_Test"/>
  <testcase name="Test_Login" time="0.856" classname="test_cases.Login_Test"/>
  <testcase name="Test_Login" time="0.015" classname="test_cases.Login_Test"/>
  <testcase name="Test_Login" time="1.544" classname="test_cases.Login_Test">
    <failure type="java.lang.AssertionError" message="expected [https://fmlcb.shaalmi.pk/admin/dashboard] but found [https://fmlcb.shaalmi.pk/login]">
      <![CDATA[java.lang.AssertionError: expected [https://fmlcb.shaalmi.pk/admin/dashboard] but found [https://fmlcb.shaalmi.pk/login]
	at org.testng.Assert.fail(Assert.java:93)
	at org.testng.Assert.failNotEquals(Assert.java:512)
	at org.testng.Assert.assertEqualsImpl(Assert.java:134)
	at org.testng.Assert.assertEquals(Assert.java:115)
	at org.testng.Assert.assertEquals(Assert.java:189)
	at org.testng.Assert.assertEquals(Assert.java:199)
	at all_operations.General_Operations.Hybrid_Ops(General_Operations.java:75)
	at test_cases.Login_Test.Test_Login(Login_Test.java:22)
	at sun.reflect.GeneratedMethodAccessor2.invoke(Unknown Source)
	at sun.reflect.DelegatingMethodAccessorImpl.invoke(DelegatingMethodAccessorImpl.java:43)
	at java.lang.reflect.Method.invoke(Method.java:498)
	at org.testng.internal.MethodInvocationHelper.invokeMethod(MethodInvocationHelper.java:108)
	at org.testng.internal.Invoker.invokeMethod(Invoker.java:661)
	at org.testng.internal.Invoker.invokeTestMethod(Invoker.java:869)
	at org.testng.internal.Invoker.invokeTestMethods(Invoker.java:1193)
	at org.testng.internal.TestMethodWorker.invokeTestMethods(TestMethodWorker.java:126)
	at org.testng.internal.TestMethodWorker.run(TestMethodWorker.java:109)
	at org.testng.TestRunner.privateRun(TestRunner.java:744)
	at org.testng.TestRunner.run(TestRunner.java:602)
	at org.testng.SuiteRunner.runTest(SuiteRunner.java:380)
	at org.testng.SuiteRunner.runSequentially(SuiteRunner.java:375)
	at org.testng.SuiteRunner.privateRun(SuiteRunner.java:340)
	at org.testng.SuiteRunner.run(SuiteRunner.java:289)
	at org.testng.SuiteRunnerWorker.runSuite(SuiteRunnerWorker.java:52)
	at org.testng.SuiteRunnerWorker.run(SuiteRunnerWorker.java:86)
	at org.testng.TestNG.runSuitesSequentially(TestNG.java:1301)
	at org.testng.TestNG.runSuitesLocally(TestNG.java:1226)
	at org.testng.TestNG.runSuites(TestNG.java:1144)
	at org.testng.TestNG.run(TestNG.java:1115)
	at org.testng.remote.AbstractRemoteTestNG.run(AbstractRemoteTestNG.java:132)
	at org.testng.remote.RemoteTestNG.initAndRun(RemoteTestNG.java:230)
	at org.testng.remote.RemoteTestNG.main(RemoteTestNG.java:76)
]]>
    </failure>
  </testcase> <!-- Test_Login -->
  <testcase name="Test_Login" time="0.066" classname="test_cases.Login_Test"/>
  <testcase name="Test_Login" time="0.967" classname="test_cases.Login_Test"/>
  <testcase name="Test_Login_Admin" time="0.180" classname="test_cases.Login_Test"/>
  <testcase name="Test_Login" time="2.007" classname="test_cases.Login_Test"/>
  <testcase name="Test_Login" time="0.041" classname="test_cases.Login_Test"/>
  <testcase name="Test_Login" time="1.550" classname="test_cases.Login_Test">
    <failure type="java.lang.AssertionError" message="expected [https://fmlcb.shaalmi.pk/admin/dashboard] but found [https://fmlcb.shaalmi.pk/login]">
      <![CDATA[java.lang.AssertionError: expected [https://fmlcb.shaalmi.pk/admin/dashboard] but found [https://fmlcb.shaalmi.pk/login]
	at org.testng.Assert.fail(Assert.java:93)
	at org.testng.Assert.failNotEquals(Assert.java:512)
	at org.testng.Assert.assertEqualsImpl(Assert.java:134)
	at org.testng.Assert.assertEquals(Assert.java:115)
	at org.testng.Assert.assertEquals(Assert.java:189)
	at org.testng.Assert.assertEquals(Assert.java:199)
	at all_operations.General_Operations.Hybrid_Ops(General_Operations.java:75)
	at test_cases.Login_Test.Test_Login(Login_Test.java:22)
	at sun.reflect.NativeMethodAccessorImpl.invoke0(Native Method)
	at sun.reflect.NativeMethodAccessorImpl.invoke(NativeMethodAccessorImpl.java:62)
	at sun.reflect.DelegatingMethodAccessorImpl.invoke(DelegatingMethodAccessorImpl.java:43)
	at java.lang.reflect.Method.invoke(Method.java:498)
	at org.testng.internal.MethodInvocationHelper.invokeMethod(MethodInvocationHelper.java:108)
	at org.testng.internal.Invoker.invokeMethod(Invoker.java:661)
	at org.testng.internal.Invoker.invokeTestMethod(Invoker.java:869)
	at org.testng.internal.Invoker.invokeTestMethods(Invoker.java:1193)
	at org.testng.internal.TestMethodWorker.invokeTestMethods(TestMethodWorker.java:126)
	at org.testng.internal.TestMethodWorker.run(TestMethodWorker.java:109)
	at org.testng.TestRunner.privateRun(TestRunner.java:744)
	at org.testng.TestRunner.run(TestRunner.java:602)
	at org.testng.SuiteRunner.runTest(SuiteRunner.java:380)
	at org.testng.SuiteRunner.runSequentially(SuiteRunner.java:375)
	at org.testng.SuiteRunner.privateRun(SuiteRunner.java:340)
	at org.testng.SuiteRunner.run(SuiteRunner.java:289)
	at org.testng.SuiteRunnerWorker.runSuite(SuiteRunnerWorker.java:52)
	at org.testng.SuiteRunnerWorker.run(SuiteRunnerWorker.java:86)
	at org.testng.TestNG.runSuitesSequentially(TestNG.java:1301)
	at org.testng.TestNG.runSuitesLocally(TestNG.java:1226)
	at org.testng.TestNG.runSuites(TestNG.java:1144)
	at org.testng.TestNG.run(TestNG.java:1115)
	at org.testng.remote.AbstractRemoteTestNG.run(AbstractRemoteTestNG.java:132)
	at org.testng.remote.RemoteTestNG.initAndRun(RemoteTestNG.java:230)
	at org.testng.remote.RemoteTestNG.main(RemoteTestNG.java:76)
]]>
    </failure>
  </testcase> <!-- Test_Login -->
  <testcase name="Test_Login" time="2.009" classname="test_cases.Login_Test"/>
  <testcase name="Test_Login" time="0.062" classname="test_cases.Login_Test"/>
  <testcase name="Test_Login" time="0.024" classname="test_cases.Login_Test"/>
  <testcase name="Test_Login_Admin" time="1.589" classname="test_cases.Login_Test"/>
  <testcase name="Test_Login" time="0.165" classname="test_cases.Login_Test"/>
  <testcase name="Test_Login_Admin" time="0.009" classname="test_cases.Login_Test"/>
  <testcase name="Test_Login" time="2.008" classname="test_cases.Login_Test"/>
  <testcase name="Test_Login" time="0.026" classname="test_cases.Login_Test"/>
  <testcase name="Test_Login" time="0.119" classname="test_cases.Login_Test"/>
  <testcase name="Test_Login" time="0.202" classname="test_cases.Login_Test"/>
  <testcase name="Test_Login" time="1.553" classname="test_cases.Login_Test"/>
  <testcase name="Test_Login_Admin" time="0.092" classname="test_cases.Login_Test"/>
  <testcase name="Test_Login" time="2.006" classname="test_cases.Login_Test"/>
  <testcase name="Test_Login" time="1.266" classname="test_cases.Login_Test"/>
  <testcase name="Test_Login" time="0.040" classname="test_cases.Login_Test"/>
</testsuite> <!-- test_cases.Login_Test -->
